Workbook

Sheet SweepValue1
A1: CASE VARIABLES | B1: source capacity
A2: SWEEP VALUE | B2: 1
A4: END TIME | B4: 2
A5: NUM STEPS | B5: 21
A6: PROJECT TIME | B6: 20
A7: DISCOUNT RATE | B7: 0.08
A8: Inflation | B8: 0
A9: Tax | B9: 0.25
A11: YEAR 1
B12: Time | C12: 0 | D12: 0.1 | E12: 0.2 | F12: 0.3 | G12: 0.4 | H12: 0.5 | I12: 0.6 | J12: 0.7 | K12: 0.8 | L12: 0.9 | M12: 1 | N12: 1.1 | O12: 1.2 | P12: 1.3 | Q12: 1.4 | R12: 1.5 | S12: 1.6 | T12: 1.7 | U12: 1.8 | V12: 1.9 | W12: 2
B13: Signal | C13: -2.5120128e-10 | D13: 0.06279052 | E13: 0.12533323 | F13: 0.18738131 | G13: 0.24868989 | H13: 0.30901699 | I13: 0.36812455 | J13: 0.42577929 | K13: 0.48175367 | L13: 0.53582679 | M13: 0.58778525 | N13: 0.63742399 | O13: 0.68454711 | P13: 0.72896863 | Q13: 0.77051324 | R13: 0.80901699 | S13: 0.84432793 | T13: 0.87630668 | U13: 0.90482705 | V13: 0.92977649 | W13: 0.95105652
A15: SOURCE | B15: a | C15: =$B$2 -> 1 | D15: =$B$2 -> 1 | E15: =$B$2 -> 1 | F15: =$B$2 -> 1 | G15: =$B$2 -> 1 | H15: =$B$2 -> 1 | I15: =$B$2 -> 1 | J15: =$B$2 -> 1 | ... W15: =$B$2 -> 1
B16: CAPEX Price | C16: 0 | D16: 0 | E16: 0 | F16: 0 | G16: 0 | H16: 0 | I16: 0 | J16: 0 | K16: 0 | L16: 0 | M16: 0 | N16: 0 | O16: 0 | P16: 0 | Q16: 0 | R16: 0 | S16: 0 | T16: 0 | U16: 0 | V16: 0 | W16: 0
B17: CAPEX Cashflow | C17: =C16*(C15/$B$35)^$B$36 -> 0 | D17: =D16*(D15/$B$35)^$B$36 -> 0 | E17: =E16*(E15/$B$35)^$B$36 -> 0 | F17: =F16*(F15/$B$35)^$B$36 -> 0 | G17: =G16*(G15/$B$35)^$B$36 -> 0 | H17: =H16*(H15/$B$35)^$B$36 -> 0 | I17: =I16*(I15/$B$35)^$B$36 -> 0 | J17: =J16*(J15/$B$35)^$B$36 -> 0 | ... W17: =W16*(W15/$B$35)^$B$36 -> 0
B18: FOM Price | C18: =$B$46 -> -100 | D18: 0 | E18: 0 | F18: 0 | G18: 0 | H18: 0 | I18: 0 | J18: 0 | K18: 0 | L18: 0 | M18: 0 | N18: 0 | O18: 0 | P18: 0 | Q18: 0 | R18: 0 | S18: 0 | T18: 0 | U18: 0 | V18: 0 | W18: 0
B19: FOM Cashflow | C19: =C18*(C15/$B$47)^$B$48 -> -10.023052 | D19: =(D15*D16)+(D15*D17)+(D15*D18) -> 0 | E19: =(E15*E16)+(E15*E17)+(E15*E18) -> 0 | F19: =(F15*F16)+(F15*F17)+(F15*F18) -> 0 | G19: =(G15*G16)+(G15*G17)+(G15*G18) -> 0 | H19: =(H15*H16)+(H15*H17)+(H15*H18) -> 0 | I19: =(I15*I16)+(I15*I17)+(I15*I18) -> 0 | J19: =(J15*J16)+(J15*J17)+(J15*J18) -> 0 | K19: =(K15*K16)+(K15*K17)+(K15*K18) -> 0 | ... W19: =(W15*W16)+(W15*W17)+(W15*W18) -> 0
B20: VOM Price | C20: =$B$57 -> -1 | D20: =$B$57 -> -1 | E20: =$B$57 -> -1 | F20: =$B$57 -> -1 | G20: =$B$57 -> -1 | H20: =$B$57 -> -1 | I20: =$B$57 -> -1 | J20: =$B$57 -> -1 | ... W20: =$B$57 -> -1
B21: VOM Cashflow | C21: =(C20*(C15/1)^1)*(1-$B$9) -> -0.75 | D21: =(D20*(D15/1)^1)*(1-$B$9) -> -0.75 | E21: =(E20*(E15/1)^1)*(1-$B$9) -> -0.75 | F21: =(F20*(F15/1)^1)*(1-$B$9) -> -0.75 | G21: =(G20*(G15/1)^1)*(1-$B$9) -> -0.75 | H21: =(H20*(H15/1)^1)*(1-$B$9) -> -0.75 | I21: =(I20*(I15/1)^1)*(1-$B$9) -> -0.75 | J21: =(J20*(J15/1)^1)*(1-$B$9) -> -0.75 | ... W21: =(W20*(W15/1)^1)*(1-$B$9) -> -0.75 | X21: TOTAL
B22: TOTAL Cashflow | C22: =C21+C19+C17 -> -10.773052 | D22: =D21+D19+D17 -> -0.75 | E22: =E21+E19+E17 -> -0.75 | F22: =F21+F19+F17 -> -0.75 | G22: =G21+G19+G17 -> -0.75 | H22: =H21+H19+H17 -> -0.75 | I22: =I21+I19+I17 -> -0.75 | J22: =J21+J19+J17 -> -0.75 | ... W22: =W21+W19+W17 -> -0.75 | X22: =SUM(C22:W22) -> -25.773052
A24: SINK | B24: a | C24: =-$B$2 -> -1 | D24: =-$B$2 -> -1 | E24: =-$B$2 -> -1 | F24: =-$B$2 -> -1 | G24: =-$B$2 -> -1 | H24: =-$B$2 -> -1 | I24: =-$B$2 -> -1 | J24: =-$B$2 -> -1 | ... W24: =-$B$2 -> -1
B25: Sales Price | C25: =$B$68 -> -31.4 | D25: =10 * -3.14 -> -31.4 | E25: =10 * -3.14 -> -31.4 | F25: =10 * -3.14 -> -31.4 | G25: =10 * -3.14 -> -31.4 | H25: =10 * -3.14 -> -31.4 | I25: =10 * -3.14 -> -31.4 | J25: =10 * -3.14 -> -31.4 | K25: =10 * -3.14 -> -31.4 | ... W25: =10 * -3.14 -> -31.4 | X25: TOTAL
B26: Sales Cashflow | C26: =C25*(C24/1)^1 -> 31.4 | D26: =D25*(D24/1)^1 -> 31.4 | E26: =E25*(E24/1)^1 -> 31.4 | F26: =F25*(F24/1)^1 -> 31.4 | G26: =G25*(G24/1)^1 -> 31.4 | H26: =H25*(H24/1)^1 -> 31.4 | I26: =I25*(I24/1)^1 -> 31.4 | J26: =J25*(J24/1)^1 -> 31.4 | ... W26: =W25*(W24/1)^1 -> 31.4 | X26: =SUM(C26:W26) -> 659.4
A28: HOURLY TOTAL | X28: TOTAL
B29: Cashflow | C29: =C26+C22 -> 20.626948 | D29: =D26+D22 -> 30.65 | E29: =E26+E22 -> 30.65 | F29: =F26+F22 -> 30.65 | G29: =G26+G22 -> 30.65 | H29: =H26+H22 -> 30.65 | I29: =I26+I22 -> 30.65 | J29: =J26+J22 -> 30.65 | ... W29: =W26+W22 -> 30.65 | X29: =SUM(C29:W29) -> 633.62695
A32: These numbers are hardcoded from the given heron input file. Changing these values will affect final answer.
A33: CAPEX
A34: reference_price (a) | B34: -10000
A35: reference_driver (D') | B35: 10
A36: scaling_factor (X) | B36: 0.999
A37: driver (D) | B37: =B2 -> 1
A38: type | B38: one-time
A39: period | B39: -
A40: taxable | B40: FALSE
A41: inflation | B41: none
A42: mult_target | B42: FALSE
A43: depreciate | B43: 5
A45: FOM
A46: reference_price (a) | B46: -100
A47: reference_driver (D') | B47: 10
A48: scaling_factor (X) | B48: 0.999
...

Sheet SweepValue2
A1: CASE VARIABLES | B1: source capacity
A2: SWEEP VALUE | B2: 2
A4: END TIME | B4: 2
A5: NUM STEPS | B5: 21
A6: PROJECT TIME | B6: 20
A7: DISCOUNT RATE | B7: 0.08
A8: Inflation | B8: 0
A9: Tax | B9: 0.25
A11: YEAR 1
B12: Time | C12: 0 | D12: 0.1 | E12: 0.2 | F12: 0.3 | G12: 0.4 | H12: 0.5 | I12: 0.6 | J12: 0.7 | K12: 0.8 | L12: 0.9 | M12: 1 | N12: 1.1 | O12: 1.2 | P12: 1.3 | Q12: 1.4 | R12: 1.5 | S12: 1.6 | T12: 1.7 | U12: 1.8 | V12: 1.9 | W12: 2
B13: Signal | C13: -2.5120128e-10 | D13: 0.06279052 | E13: 0.12533323 | F13: 0.18738131 | G13: 0.24868989 | H13: 0.30901699 | I13: 0.36812455 | J13: 0.42577929 | K13: 0.48175367 | L13: 0.53582679 | M13: 0.58778525 | N13: 0.63742399 | O13: 0.68454711 | P13: 0.72896863 | Q13: 0.77051324 | R13: 0.80901699 | S13: 0.84432793 | T13: 0.87630668 | U13: 0.90482705 | V13: 0.92977649 | W13: 0.95105652
A15: SOURCE | B15: a | C15: =$B$2 -> 2 | D15: =$B$2 -> 2 | E15: =$B$2 -> 2 | F15: =$B$2 -> 2 | G15: =$B$2 -> 2 | H15: =$B$2 -> 2 | I15: =$B$2 -> 2 | J15: =$B$2 -> 2 | ... W15: =$B$2 -> 2
B16: CAPEX Price | C16: 0 | D16: 0 | E16: 0 | F16: 0 | G16: 0 | H16: 0 | I16: 0 | J16: 0 | K16: 0 | L16: 0 | M16: 0 | N16: 0 | O16: 0 | P16: 0 | Q16: 0 | R16: 0 | S16: 0 | T16: 0 | U16: 0 | V16: 0 | W16: 0
B17: CAPEX Cashflow | C17: =C16*(C15/$B$36)^$B$37 -> 0 | D17: =D16*(D15/$B$36)^$B$37 -> 0 | E17: =E16*(E15/$B$36)^$B$37 -> 0 | F17: =F16*(F15/$B$36)^$B$37 -> 0 | G17: =G16*(G15/$B$36)^$B$37 -> 0 | H17: =H16*(H15/$B$36)^$B$37 -> 0 | I17: =I16*(I15/$B$36)^$B$37 -> 0 | J17: =J16*(J15/$B$36)^$B$37 -> 0 | ... W17: =W16*(W15/$B$36)^$B$37 -> 0
B18: FOM Price | C18: =$B$47 -> -100 | D18: 0 | E18: 0 | F18: 0 | G18: 0 | H18: 0 | I18: 0 | J18: 0 | K18: 0 | L18: 0 | M18: 0 | N18: 0 | O18: 0 | P18: 0 | Q18: 0 | R18: 0 | S18: 0 | T18: 0 | U18: 0 | V18: 0 | W18: 0
B19: FOM Cashflow | C19: =C18*(C15/$B$48)^$B$49 -> -20.032215 | D19: =(D15*D16)+(D15*D17)+(D15*D18) -> 0 | E19: =(E15*E16)+(E15*E17)+(E15*E18) -> 0 | F19: =(F15*F16)+(F15*F17)+(F15*F18) -> 0 | G19: =(G15*G16)+(G15*G17)+(G15*G18) -> 0 | H19: =(H15*H16)+(H15*H17)+(H15*H18) -> 0 | I19: =(I15*I16)+(I15*I17)+(I15*I18) -> 0 | J19: =(J15*J16)+(J15*J17)+(J15*J18) -> 0 | K19: =(K15*K16)+(K15*K17)+(K15*K18) -> 0 | ... W19: =(W15*W16)+(W15*W17)+(W15*W18) -> 0
B20: VOM Price | C20: =$B$58 -> -1 | D20: =$B$58 -> -1 | E20: =$B$58 -> -1 | F20: =$B$58 -> -1 | G20: =$B$58 -> -1 | H20: =$B$58 -> -1 | I20: =$B$58 -> -1 | J20: =$B$58 -> -1 | ... W20: =$B$58 -> -1
B21: VOM Cashflow | C21: =(C20*(C15/1)^1)*(1-$B$9) -> -1.5 | D21: =(D20*(D15/1)^1)*(1-$B$9) -> -1.5 | E21: =(E20*(E15/1)^1)*(1-$B$9) -> -1.5 | F21: =(F20*(F15/1)^1)*(1-$B$9) -> -1.5 | G21: =(G20*(G15/1)^1)*(1-$B$9) -> -1.5 | H21: =(H20*(H15/1)^1)*(1-$B$9) -> -1.5 | I21: =(I20*(I15/1)^1)*(1-$B$9) -> -1.5 | J21: =(J20*(J15/1)^1)*(1-$B$9) -> -1.5 | ... W21: =(W20*(W15/1)^1)*(1-$B$9) -> -1.5 | X21: TOTAL
B22: TOTAL Cashflow | C22: =C21+C19+C17 -> -21.532215 | D22: =D21+D19+D17 -> -1.5 | E22: =E21+E19+E17 -> -1.5 | F22: =F21+F19+F17 -> -1.5 | G22: =G21+G19+G17 -> -1.5 | H22: =H21+H19+H17 -> -1.5 | I22: =I21+I19+I17 -> -1.5 | J22: =J21+J19+J17 -> -1.5 | ... W22: =W21+W19+W17 -> -1.5 | X22: =SUM(C22:W22) -> -51.532215
A24: SINK | B24: a | C24: =-$B$2 -> -2 | D24: =-$B$2 -> -2 | E24: =-$B$2 -> -2 | F24: =-$B$2 -> -2 | G24: =-$B$2 -> -2 | H24: =-$B$2 -> -2 | I24: =-$B$2 -> -2 | J24: =-$B$2 -> -2 | ... W24: =-$B$2 -> -2
B25: Sales Price | C25: =$B$69 -> -31.4 | D25: =10 * -3.14 -> -31.4 | E25: =10 * -3.14 -> -31.4 | F25: =10 * -3.14 -> -31.4 | G25: =10 * -3.14 -> -31.4 | H25: =10 * -3.14 -> -31.4 | I25: =10 * -3.14 -> -31.4 | J25: =10 * -3.14 -> -31.4 | K25: =10 * -3.14 -> -31.4 | ... W25: =10 * -3.14 -> -31.4 | X25: TOTAL
B26: Sales Cashflow | C26: =C25*(C24/1)^1 -> 62.8 | D26: =D25*(D24/1)^1 -> 62.8 | E26: =E25*(E24/1)^1 -> 62.8 | F26: =F25*(F24/1)^1 -> 62.8 | G26: =G25*(G24/1)^1 -> 62.8 | H26: =H25*(H24/1)^1 -> 62.8 | I26: =I25*(I24/1)^1 -> 62.8 | J26: =J25*(J24/1)^1 -> 62.8 | ... W26: =W25*(W24/1)^1 -> 62.8 | X26: =SUM(C26:W26) -> 1318.8
A28: HOURLY TOTAL | X28: TOTAL
B29: Cashflow | C29: =C26+C22 -> 41.267785 | D29: =D26+D22 -> 61.3 | E29: =E26+E22 -> 61.3 | F29: =F26+F22 -> 61.3 | G29: =G26+G22 -> 61.3 | H29: =H26+H22 -> 61.3 | I29: =I26+I22 -> 61.3 | J29: =J26+J22 -> 61.3 | ... W29: =W26+W22 -> 61.3 | X29: =SUM(C29:W29) -> 1267.2678
A33: These numbers are hardcoded from the given heron input file. Changing these values will effect final answer.
A34: CAPEX
A35: reference_price (a) | B35: -10000
A36: reference_driver (D') | B36: 10
A37: scaling_factor (X) | B37: 0.999
A38: driver (D) | B38: =B2 -> 2
A39: type | B39: one-time
A40: period | B40: -
A41: taxable | B41: FALSE
A42: inflation | B42: none
A43: mult_target | B43: FALSE
A44: depreciate | B44: 5
A46: FOM
A47: reference_price (a) | B47: -100
A48: reference_driver (D') | B48: 10
A49: scaling_factor (X) | B49: 0.999
...

Sheet ProjectCashflows
C1: CASE VARIABLES | D1: source capacity
C2: SweepValue1 | D2: 1
C3: SweepValue2 | D3: 2
C5: END TIME | D5: 2
C6: NUM STEPS | D6: 21
C7: PROJECT TIME | D7: 20
C8: DISCOUNT RATE | D8: 0.08
C9: Inflation | D9: 0
C10: Tax | D10: 0.25
C12: Source MACRS | D12: 0.15 | AJ12: YEARS | AL12: 0 | AM12: 1 | AN12: 2 | AO12: 3 | AP12: 4 | AQ12: 5 | AR12: 6 | AS12: 7 | AT12: 8 | AU12: 9 | AV12: 10 | AW12: 11 | AX12: 12 | AY12: 13 | AZ12: 14 | BA12: 15 | BB12: 16 | BC12: 17 | BD12: 18 | BE12: 19 | BF12: 20 | BG12: SUM | BR12: YEARS | BT12: 0 | BU12: 1 | BV12: 2 | BW12: 3 | BX12: 4 | BY12: 5 | BZ12: 6 | CA12: 7 | CB12: 8 | CC12: 9 | CD12: 10 | CE12: 11 | CF12: 12 | CG12: 13 | CH12: 14 | CI12: 15 | CJ12: 16 | CK12: 17 | CL12: 18 | CM12: 19 | CN12: 20 | CO12: SUM
C13: Source Lifetime | D13: 20 | AJ13: Tax Fraction | AL13: =1-$D$10 -> 0.75 | AM13: =1-$D$10 -> 0.75 | AN13: =1-$D$10 -> 0.75 | AO13: =1-$D$10 -> 0.75 | AP13: =1-$D$10 -> 0.75 | AQ13: =1-$D$10 -> 0.75 | AR13: =1-$D$10 -> 0.75 | AS13: =1-$D$10 -> 0.75 | ... BF13: =1-$D$10 -> 0.75 | BR13: Tax Fraction | BT13: =1-$D$10 -> 0.75 | BU13: =1-$D$10 -> 0.75 | BV13: =1-$D$10 -> 0.75 | BW13: =1-$D$10 -> 0.75 | BX13: =1-$D$10 -> 0.75 | BY13: =1-$D$10 -> 0.75 | BZ13: =1-$D$10 -> 0.75 | CA13: =1-$D$10 -> 0.75 | ... CN13: =1-$D$10 -> 0.75
AJ14: Discount Rate | AL14: =1/(1+$D$8)^AL12 -> 1 | AM14: =1/(1+$D$8)^AM12 -> 0.92592593 | AN14: =1/(1+$D$8)^AN12 -> 0.85733882 | AO14: =1/(1+$D$8)^AO12 -> 0.79383224 | AP14: =1/(1+$D$8)^AP12 -> 0.73502985 | AQ14: =1/(1+$D$8)^AQ12 -> 0.6805832 | AR14: =1/(1+$D$8)^AR12 -> 0.63016963 | AS14: =1/(1+$D$8)^AS12 -> 0.5834904 | ... BF14: =1/(1+$D$8)^BF12 -> 0.21454821 | BR14: Discount Rate | BT14: =1/(1+$D$8)^BT12 -> 1 | BU14: =1/(1+$D$8)^BU12 -> 0.92592593 | BV14: =1/(1+$D$8)^BV12 -> 0.85733882 | BW14: =1/(1+$D$8)^BW12 -> 0.79383224 | BX14: =1/(1+$D$8)^BX12 -> 0.73502985 | BY14: =1/(1+$D$8)^BY12 -> 0.6805832 | BZ14: =1/(1+$D$8)^BZ12 -> 0.63016963 | CA14: =1/(1+$D$8)^CA12 -> 0.5834904 | ... CN14: =1/(1+$D$8)^CN12 -> 0.21454821
C15: YEARS | E15: 0 | F15: 1 | G15: 2 | H15: 3 | I15: 4 | J15: 5 | K15: 6 | L15: 7 | M15: 8 | N15: 9 | O15: 10 | P15: 11 | Q15: 12 | R15: 13 | S15: 14 | T15: 15 | U15: 16 | V15: 17 | W15: 18 | X15: 19 | Y15: 20 | Z15: SUM | AJ15: MACRS Ammortization 15-Yr | AL15: 0 | AM15: 0 | AN15: 0 | AO15: 0 | AP15: 0 | AQ15: 0 | AR15: 0 | AS15: 0 | AT15: 0 | AU15: 0 | AV15: 0 | AW15: 0 | AX15: 0 | AY15: 0 | AZ15: 0 | BA15: 0 | BB15: 0 | BC15: 0 | BD15: 0 | BE15: 0 | BF15: 0 | BR15: MACRS Ammortization 15-Yr | BT15: 0 | BU15: 0 | BV15: 0 | BW15: 0 | BX15: 0 | BY15: 0 | BZ15: 0 | CA15: 0 | CB15: 0 | CC15: 0 | CD15: 0 | CE15: 0 | CF15: 0 | CG15: 0 | CH15: 0 | CI15: 0 | CJ15: 0 | CK15: 0 | CL15: 0 | CM15: 0 | CN15: 0
C16: Tax Fraction | E16: =1-$D$10 -> 0.75 | F16: =1-$D$10 -> 0.75 | G16: =1-$D$10 -> 0.75 | H16: =1-$D$10 -> 0.75 | I16: =1-$D$10 -> 0.75 | J16: =1-$D$10 -> 0.75 | K16: =1-$D$10 -> 0.75 | L16: =1-$D$10 -> 0.75 | ... Y16: =1-$D$10 -> 0.75
C17: Discount Rate | E17: =1/(1+$D$8)^E15 -> 1 | F17: =1/(1+$D$8)^F15 -> 0.92592593 | G17: =1/(1+$D$8)^G15 -> 0.85733882 | H17: =1/(1+$D$8)^H15 -> 0.79383224 | I17: =1/(1+$D$8)^I15 -> 0.73502985 | J17: =1/(1+$D$8)^J15 -> 0.6805832 | K17: =1/(1+$D$8)^K15 -> 0.63016963 | L17: =1/(1+$D$8)^L15 -> 0.5834904 | ... Y17: =1/(1+$D$8)^Y15 -> 0.21454821
C18: MACRS Ammortization 15-Yr | E18: 0 | F18: 0 | G18: 0 | H18: 0 | I18: 0 | J18: 0 | K18: 0 | L18: 0 | M18: 0 | N18: 0 | O18: 0 | P18: 0 | Q18: 0 | R18: 0 | S18: 0 | T18: 0 | U18: 0 | V18: 0 | W18: 0 | X18: 0 | Y18: 0 | AB18: StartTime=0
B19: SweepValue1 | C19: CAPEX | E19: =$D$86*($D$2/$D$87)^$D$88 -> -1002.3052 | F19: 0 | G19: 0 | H19: 0 | I19: 0 | J19: 0 | K19: 0 | L19: 0 | M19: 0 | N19: 0 | O19: 0 | P19: 0 | Q19: 0 | R19: 0 | S19: 0 | T19: 0 | U19: 0 | V19: 0 | W19: 0 | X19: 0 | Y19: 0 | AB19: CORRECT
C20: Summed Hourly Cashflow (already taxed) | E20: 0 | F20: =SweepValue1!$X$29*F17 -> 586.69162 | G20: =SweepValue1!$X$29*G17 -> 543.23298 | H20: =SweepValue1!$X$29*H17 -> 502.9935 | I20: =SweepValue1!$X$29*I17 -> 465.73472 | J20: =SweepValue1!$X$29*J17 -> 431.23585 | K20: =SweepValue1!$X$29*K17 -> 399.29246 | L20: =SweepValue1!$X$29*L17 -> 369.71524 | M20: =SweepValue1!$X$29*M17 -> 342.32892 | ... Y20: =SweepValue1!$X$29*Y17 -> 135.94353 | Z20: =SUM(E20:Y20) -> 6221.0428 | AA20: =SUM(Z20:Z23) -> 5469.3138
C21: CAPEX Cashflow | E21: =E19*E16 -> -751.72893 | F21: =F19*F16 -> 0 | G21: =G19*G16 -> 0 | H21: =H19*H16 -> 0 | I21: =I19*I16 -> 0 | J21: =J19*J16 -> 0 | K21: =K19*K16 -> 0 | L21: =L19*L16 -> 0 | ... Y21: =Y19*Y16 -> 0 | Z21: =SUM(E21:Y21) -> -751.72893
C22: Depreciation + | E22: =-$E$19*E17/100*E18 -> 0 | F22: =-$E$19*F17/100*F18 -> 0 | G22: =-$E$19*G17/100*G18 -> 0 | H22: =-$E$19*H17/100*H18 -> 0 | I22: =-$E$19*I17/100*I18 -> 0 | J22: =-$E$19*J17/100*J18 -> 0 | K22: =-$E$19*K17/100*K18 -> 0 | L22: =-$E$19*L17/100*L18 -> 0 | ... Y22: =-$E$19*Y17/100*Y18 -> 0 | Z22: =SUM(E22:Y22) -> 0
C23: Depreciation - | E23: =E18*E17/100*$E$21 -> 0 | F23: =F18*F17/100*$E$21 -> 0 | G23: =G18*G17/100*$E$21 -> 0 | H23: =H18*H17/100*$E$21 -> 0 | I23: =I18*I17/100*$E$21 -> 0 | J23: =J18*J17/100*$E$21 -> 0 | K23: =K18*K17/100*$E$21 -> 0 | L23: =L18*L17/100*$E$21 -> 0 | ... X23: =X18*X17/100*$E$21 -> 0 | Y23: =Y18*Y17*$E$21 -> 0 | Z23: =SUM(E23:Y23) -> 0
B24: SweepValue2 | C24: CAPEX | E24: =$D$86*($D$3/$D$87)^$D$88 -> -2003.2215 | F24: 0 | G24: 0 | H24: 0 | I24: 0 | J24: 0 | K24: 0 | L24: 0 | M24: 0 | N24: 0 | O24: 0 | P24: 0 | Q24: 0 | R24: 0 | S24: 0 | T24: 0 | U24: 0 | V24: 0 | W24: 0 | X24: 0 | Y24: 0
C25: Summed Hourly Cashflow (already taxed) | E25: 0 | F25: =SweepValue2!$X$29*F17 -> 1173.3961 | G25: =SweepValue2!$X$29*G17 -> 1086.4779 | H25: =SweepValue2!$X$29*H17 -> 1005.998 | I25: =SweepValue2!$X$29*I17 -> 931.47965 | J25: =SweepValue2!$X$29*J17 -> 862.48116 | K25: =SweepValue2!$X$29*K17 -> 798.59367 | L25: =SweepValue2!$X$29*L17 -> 739.43858 | M25: =SweepValue2!$X$29*M17 -> 684.66535 | ... Y25: =SweepValue2!$X$29*Y17 -> 271.89003 | Z25: =SUM(E25:Y25) -> 12442.222 | AA25: =SUM(Z25:Z28) -> 10939.806
C26: CAPEX Cashflow | E26: =E24*E16 -> -1502.4161 | F26: 0 | G26: 0 | H26: 0 | I26: 0 | J26: 0 | K26: 0 | L26: 0 | M26: 0 | N26: 0 | O26: 0 | P26: 0 | Q26: 0 | R26: 0 | S26: 0 | T26: 0 | U26: 0 | V26: 0 | W26: 0 | X26: 0 | Y26: 0 | Z26: =SUM(E26:Y26) -> -1502.4161
C27: Depreciation + | E27: =-$E$24*E17*E18/100 -> 0 | F27: =-$E$24*F17*F18/100 -> 0 | G27: =-$E$24*G17*G18/100 -> 0 | H27: =-$E$24*H17*H18/100 -> 0 | I27: =-$E$24*I17*I18/100 -> 0 | J27: =-$E$24*J17*J18/100 -> 0 | K27: =-$E$24*K17*K18/100 -> 0 | L27: =-$E$24*L17*L18/100 -> 0 | ... Y27: =-$E$24*Y17*Y18/100 -> 0 | Z27: =SUM(E27:Y27) -> 0
C28: Depreciation - | E28: =$E$26*E17*E18/100 -> 0 | F28: =$E$26*F17*F18/100 -> 0 | G28: =$E$26*G17*G18/100 -> 0 | H28: =$E$26*H17*H18/100 -> 0 | I28: =$E$26*I17*I18/100 -> 0 | J28: =$E$26*J17*J18/100 -> 0 | K28: =$E$26*K17*K18/100 -> 0 | L28: =$E$26*L17*L18/100 -> 0 | ... Y28: =$E$26*Y17*Y18/100 -> 0 | Z28: =SUM(E28:Y28) -> 0 | AJ28: StartTime + Lifetime < ProjectTime Lifetime > ProjectTime | BR28: StartTime + Lifetime > ProjectTime TEAL Errors Out
C32: Lifetime <= ProjectTime
BI34: Lifetime = 25 | CQ34: Lifetime = 40
AB35: StartTime=-5 | AJ35: YEARS | AL35: 0 | AM35: 1 | AN35: 2 | AO35: 3 | AP35: 4 | AQ35: 5 | AR35: 6 | AS35: 7 | AT35: 8 | AU35: 9 | AV35: 10 | AW35: 11 | AX35: 12 | AY35: 13 | AZ35: 14 | BA35: 15 | BB35: 16 | BC35: 17 | BD35: 18 | BE35: 19 | BF35: 20 | BI35: StartTime=-10 | BR35: YEARS | BT35: 0 | BU35: 1 | BV35: 2 | BW35: 3 | BX35: 4 | BY35: 5 | BZ35: 6 | CA35: 7 | CB35: 8 | CC35: 9 | CD35: 10 | CE35: 11 | CF35: 12 | CG35: 13 | CH35: 14 | CI35: 15 | CJ35: 16 | CK35: 17 | CL35: 18 | CM35: 19 | CN35: 20 | CQ35: StartTime=-5
B36: SweepValue1 | C36: CAPEX | E36: =$D$86*($D$2/$D$87)^$D$88 -> -1002.3052 | F36: 0 | G36: 0 | H36: 0 | I36: 0 | J36: 0 | K36: 0 | L36: 0 | M36: 0 | N36: 0 | O36: 0 | P36: 0 | Q36: 0 | R36: 0 | S36: 0 | T36: 0 | U36: 0 | V36: 0 | W36: 0 | X36: 0 | Y36: 0 | AB36: CORRECT | AI36: SweepValue1 | AJ36: CAPEX | AL36: =$D$86*($D$2/$D$87)^$D$88 -> -1002.3052 | AM36: 0 | AN36: 0 | AO36: 0 | AP36: 0 | AQ36: 0 | AR36: 0 | AS36: 0 | AT36: 0 | AU36: 0 | AV36: 0 | AW36: 0 | AX36: 0 | AY36: 0 | AZ36: 0 | BA36: 0 | BB36: 0 | BC36: 0 | BD36: 0 | BE36: 0 | BF36: 0 | BI36: CORRECT | BQ36: SweepValue1 | BR36: CAPEX | BT36: =$D$86*($D$2/$D$87)^$D$88 -> -1002.3052 | BU36: 0 | BV36: 0 | BW36: 0 | BX36: 0 | BY36: 0 | BZ36: 0 | CA36: 0 | CB36: 0 | CC36: 0 | CD36: 0 | CE36: 0 | CF36: 0 | CG36: 0 | CH36: 0 | CI36: 0 | CJ36: 0 | CK36: 0 | CL36: 0 | CM36: 0 | CN36: 0 | CQ36: ERROR
C37: Summed Hourly Cashflow (already taxed) | E37: 0 | F37: =F20 -> 586.69162 | G37: =G20 -> 543.23298 | H37: =H20 -> 502.9935 | I37: =I20 -> 465.73472 | J37: =J20 -> 431.23585 | K37: =K20 -> 399.29246 | L37: =L20 -> 369.71524 | M37: =M20 -> 342.32892 | ... Y37: =Y20 -> 135.94353 | Z37: =SUM(E37:Y37) -> 6221.0428 | AA37: =SUM(Z37:Z40) -> 5984.0665 | AJ37: Summed Hourly Cashflow (already taxed) | AL37: 0 | AM37: =F37 -> 586.69162 | AN37: =G37 -> 543.23298 | AO37: =H37 -> 502.9935 | AP37: =I37 -> 465.73472 | AQ37: =J37 -> 431.23585 | AR37: =K37 -> 399.29246 | AS37: =L37 -> 369.71524 | AT37: =M37 -> 342.32892 | ... BF37: =Y37 -> 135.94353 | BG37: =SUM(AL37:BF37) -> 6221.0428 | BH37: =SUM(BG37:BG40) -> 5984.0665 | BR37: Summed Hourly Cashflow (already taxed) | BT37: 0 | BU37: =AM37 -> 586.69162 | BV37: =AN37 -> 543.23298 | BW37: =AO37 -> 502.9935 | BX37: =AP37 -> 465.73472 | BY37: =AQ37 -> 431.23585 | BZ37: =AR37 -> 399.29246 | CA37: =AS37 -> 369.71524 | CB37: =AT37 -> 342.32892 | ... CN37: =BF37 -> 135.94353 | CO37: =SUM(BT37:CN37) -> 6221.0428 | CP37: =SUM(CO37:CO40) -> 6221.0428
C38: CAPEX Cashflow | E38: =E36*E31 -> 0 | F38: =F36*F31 -> 0 | G38: =G36*G31 -> 0 | H38: =H36*H31 -> 0 | I38: =I36*I31 -> 0 | J38: =J36*J31 -> 0 | K38: =K36*K31 -> 0 | L38: =L36*L31 -> 0 | ... S38: =S36*S31 -> 0 | T38: =E36*T16*T17 -> -236.97631 | U38: =U36*U31 -> 0 | V38: =V36*V31 -> 0 | W38: =W36*W31 -> 0 | X38: =X36*X31 -> 0 | Y38: =Y36*Y31 -> 0 | Z38: =SUM(E38:Y38) -> -236.97631 | AJ38: CAPEX Cashflow | AL38: =AL36*AL31 -> 0 | AM38: =AM36*AM31 -> 0 | AN38: =AN36*AN31 -> 0 | AO38: =AO36*AO31 -> 0 | AP38: =AP36*AP31 -> 0 | AQ38: =AQ36*AQ31 -> 0 | AR38: =AR36*AR31 -> 0 | AS38: =AS36*AS31 -> 0 | ... AZ38: =AZ36*AZ31 -> 0 | BA38: =AL36*BA13*BA14 -> -236.97631 | BB38: =BB36*BB31 -> 0 | BC38: =BC36*BC31 -> 0 | BD38: =BD36*BD31 -> 0 | BE38: =BE36*BE31 -> 0 | BF38: =BF36*BF31 -> 0 | BG38: =SUM(AL38:BF38) -> -236.97631 | BR38: CAPEX Cashflow | BT38: =BT36*BT31 -> 0 | BU38: =BU36*BU31 -> 0 | BV38: =BV36*BV31 -> 0 | BW38: =BW36*BW31 -> 0 | BX38: =BX36*BX31 -> 0 | BY38: =BY36*BY31 -> 0 | BZ38: =BZ36*BZ31 -> 0 | CA38: =CA36*CA31 -> 0 | ... CH38: =CH36*CH31 -> 0 | CI38: =BT36*CI16*CI17 -> 0 | CJ38: =CJ36*CJ31 -> 0 | CK38: =CK36*CK31 -> 0 | CL38: =CL36*CL31 -> 0 | CM38: =CM36*CM31 -> 0 | CN38: =CN36*CN31 -> 0 | CO38: =SUM(BT38:CN38) -> 0
C39: Depreciation + | E39: =-$E$19*E32/100*E35 -> 0 | F39: =-$E$19*F32/100*F35 -> 0 | G39: =-$E$19*G32/100*G35 -> 0 | H39: =-$E$19*H32/100*H35 -> 0 | I39: =-$E$19*I32/100*I35 -> 0 | J39: =-$E$19*J32/100*J35 -> 0 | K39: =-$E$19*K32/100*K35 -> 0 | L39: =-$E$19*L32/100*L35 -> 0 | ... Y39: =-$E$19*Y32/100*Y35 -> 0 | Z39: =SUM(E39:Y39) -> 0 | AJ39: Depreciation + | AL39: =-$E$19*AL32/100*AL35 -> 0 | AM39: =-$E$19*AM32/100*AM35 -> 0 | AN39: =-$E$19*AN32/100*AN35 -> 0 | AO39: =-$E$19*AO32/100*AO35 -> 0 | AP39: =-$E$19*AP32/100*AP35 -> 0 | AQ39: =-$E$19*AQ32/100*AQ35 -> 0 | AR39: =-$E$19*AR32/100*AR35 -> 0 | AS39: =-$E$19*AS32/100*AS35 -> 0 | ... BF39: =-$E$19*BF32/100*BF35 -> 0 | BG39: =SUM(AL39:BF39) -> 0 | BR39: Depreciation + | BT39: =-$E$19*BT32/100*BT35 -> 0 | BU39: =-$E$19*BU32/100*BU35 -> 0 | BV39: =-$E$19*BV32/100*BV35 -> 0 | BW39: =-$E$19*BW32/100*BW35 -> 0 | BX39: =-$E$19*BX32/100*BX35 -> 0 | BY39: =-$E$19*BY32/100*BY35 -> 0 | BZ39: =-$E$19*BZ32/100*BZ35 -> 0 | CA39: =-$E$19*CA32/100*CA35 -> 0 | ... CN39: =-$E$19*CN32/100*CN35 -> 0 | CO39: =SUM(BT39:CN39) -> 0
C40: Depreciation - | E40: =E35*E32/100*$E$21 -> 0 | F40: =F35*F32/100*$E$21 -> 0 | G40: =G35*G32/100*$E$21 -> 0 | H40: =H35*H32/100*$E$21 -> 0 | I40: =I35*I32/100*$E$21 -> 0 | J40: =J35*J32/100*$E$21 -> 0 | K40: =K35*K32/100*$E$21 -> 0 | L40: =L35*L32/100*$E$21 -> 0 | ... X40: =X35*X32/100*$E$21 -> 0 | Y40: =Y35*Y32*$E$21 -> 0 | Z40: =SUM(E40:Y40) -> 0 | AJ40: Depreciation - | AL40: =AL35*AL32/100*$E$21 -> 0 | AM40: =AM35*AM32/100*$E$21 -> 0 | AN40: =AN35*AN32/100*$E$21 -> 0 | AO40: =AO35*AO32/100*$E$21 -> 0 | AP40: =AP35*AP32/100*$E$21 -> 0 | AQ40: =AQ35*AQ32/100*$E$21 -> 0 | AR40: =AR35*AR32/100*$E$21 -> 0 | AS40: =AS35*AS32/100*$E$21 -> 0 | ... BE40: =BE35*BE32/100*$E$21 -> 0 | BF40: =BF35*BF32*$E$21 -> 0 | BG40: =SUM(AL40:BF40) -> 0 | BR40: Depreciation - | BT40: =BT35*BT32/100*$E$21 -> 0 | BU40: =BU35*BU32/100*$E$21 -> 0 | BV40: =BV35*BV32/100*$E$21 -> 0 | BW40: =BW35*BW32/100*$E$21 -> 0 | BX40: =BX35*BX32/100*$E$21 -> 0 | BY40: =BY35*BY32/100*$E$21 -> 0 | BZ40: =BZ35*BZ32/100*$E$21 -> 0 | CA40: =CA35*CA32/100*$E$21 -> 0 | ... CM40: =CM35*CM32/100*$E$21 -> 0 | CN40: =CN35*CN32*$E$21 -> 0 | CO40: =SUM(BT40:CN40) -> 0
B41: SweepValue2 | C41: CAPEX | E41: =$D$86*($D$3/$D$87)^$D$88 -> -2003.2215 | F41: 0 | G41: 0 | H41: 0 | I41: 0 | J41: 0 | K41: 0 | L41: 0 | M41: 0 | N41: 0 | O41: 0 | P41: 0 | Q41: 0 | R41: 0 | S41: 0 | T41: 0 | U41: 0 | V41: 0 | W41: 0 | X41: 0 | Y41: 0 | AI41: SweepValue2 | AJ41: CAPEX | AL41: =$D$86*($D$3/$D$87)^$D$88 -> -2003.2215 | AM41: 0 | AN41: 0 | AO41: 0 | AP41: 0 | AQ41: 0 | AR41: 0 | AS41: 0 | AT41: 0 | AU41: 0 | AV41: 0 | AW41: 0 | AX41: 0 | AY41: 0 | AZ41: 0 | BA41: 0 | BB41: 0 | BC41: 0 | BD41: 0 | BE41: 0 | BF41: 0 | BQ41: SweepValue2 | BR41: CAPEX | BT41: =$D$86*($D$3/$D$87)^$D$88 -> -2003.2215 | BU41: 0 | BV41: 0 | BW41: 0 | BX41: 0 | BY41: 0 | BZ41: 0 | CA41: 0 | CB41: 0 | CC41: 0 | CD41: 0 | CE41: 0 | CF41: 0 | CG41: 0 | CH41: 0 | CI41: 0 | CJ41: 0 | CK41: 0 | CL41: 0 | CM41: 0 | CN41: 0
C42: Summed Hourly Cashflow (already taxed) | E42: 0 | F42: =F25 -> 1173.3961 | G42: =G25 -> 1086.4779 | H42: =H25 -> 1005.998 | I42: =I25 -> 931.47965 | J42: =J25 -> 862.48116 | K42: =K25 -> 798.59367 | L42: =L25 -> 739.43858 | M42: =M25 -> 684.66535 | ... Y42: =Y25 -> 271.89003 | Z42: =SUM(E42:Y42) -> 12442.222 | AA42: =SUM(Z42:Z45) -> 11968.598 | AJ42: Summed Hourly Cashflow (already taxed) | AL42: 0 | AM42: =F42 -> 1173.3961 | AN42: =G42 -> 1086.4779 | AO42: =H42 -> 1005.998 | AP42: =I42 -> 931.47965 | AQ42: =J42 -> 862.48116 | AR42: =K42 -> 798.59367 | AS42: =L42 -> 739.43858 | AT42: =M42 -> 684.66535 | ... BF42: =Y42 -> 271.89003 | BG42: =SUM(AL42:BF42) -> 12442.222 | BH42: =SUM(BG42:BG45) -> 11968.598 | BR42: Summed Hourly Cashflow (already taxed) | BT42: 0 | BU42: =AM42 -> 1173.3961 | BV42: =AN42 -> 1086.4779 | BW42: =AO42 -> 1005.998 | BX42: =AP42 -> 931.47965 | BY42: =AQ42 -> 862.48116 | BZ42: =AR42 -> 798.59367 | CA42: =AS42 -> 739.43858 | CB42: =AT42 -> 684.66535 | ... CN42: =BF42 -> 271.89003 | CO42: =SUM(BT42:CN42) -> 12442.222 | CP42: =SUM(CO42:CO45) -> 12442.222
C43: CAPEX Cashflow | E43: =E41*E31 -> 0 | F43: 0 | G43: 0 | H43: 0 | I43: 0 | J43: 0 | K43: 0 | L43: 0 | M43: 0 | N43: 0 | O43: 0 | P43: 0 | Q43: 0 | R43: 0 | S43: 0 | T43: =E41*T16*T17 -> -473.62421 | U43: 0 | V43: 0 | W43: 0 | X43: 0 | Y43: 0 | Z43: =SUM(E43:Y43) -> -473.62421 | AJ43: CAPEX Cashflow | AL43: =AL41*AL31 -> 0 | AM43: 0 | AN43: 0 | AO43: 0 | AP43: 0 | AQ43: 0 | AR43: 0 | AS43: 0 | AT43: 0 | AU43: 0 | AV43: 0 | AW43: 0 | AX43: 0 | AY43: 0 | AZ43: 0 | BA43: =AL41*BA13*BA14 -> -473.62421 | BB43: 0 | BC43: 0 | BD43: 0 | BE43: 0 | BF43: 0 | BG43: =SUM(AL43:BF43) -> -473.62421 | BR43: CAPEX Cashflow | BT43: =BT41*BT31 -> 0 | BU43: 0 | BV43: 0 | BW43: 0 | BX43: 0 | BY43: 0 | BZ43: 0 | CA43: 0 | CB43: 0 | CC43: 0 | CD43: 0 | CE43: 0 | CF43: 0 | CG43: 0 | CH43: 0 | CI43: =BT41*CI16*CI17 -> 0 | CJ43: 0 | CK43: 0 | CL43: 0 | CM43: 0 | CN43: 0 | CO43: =SUM(BT43:CN43) -> 0
C44: Depreciation + | E44: =-$E$24*E32*E35/100 -> 0 | F44: =-$E$24*F32*F35/100 -> 0 | G44: =-$E$24*G32*G35/100 -> 0 | H44: =-$E$24*H32*H35/100 -> 0 | I44: =-$E$24*I32*I35/100 -> 0 | J44: =-$E$24*J32*J35/100 -> 0 | K44: =-$E$24*K32*K35/100 -> 0 | L44: =-$E$24*L32*L35/100 -> 0 | ... Y44: =-$E$24*Y32*Y35/100 -> 0 | Z44: =SUM(E44:Y44) -> 0 | AJ44: Depreciation + | AL44: =-$E$24*AL32*AL35/100 -> 0 | AM44: =-$E$24*AM32*AM35/100 -> 0 | AN44: =-$E$24*AN32*AN35/100 -> 0 | AO44: =-$E$24*AO32*AO35/100 -> 0 | AP44: =-$E$24*AP32*AP35/100 -> 0 | AQ44: =-$E$24*AQ32*AQ35/100 -> 0 | AR44: =-$E$24*AR32*AR35/100 -> 0 | AS44: =-$E$24*AS32*AS35/100 -> 0 | ... BF44: =-$E$24*BF32*BF35/100 -> 0 | BG44: =SUM(AL44:BF44) -> 0 | BR44: Depreciation + | BT44: =-$E$24*BT32*BT35/100 -> 0 | BU44: =-$E$24*BU32*BU35/100 -> 0 | BV44: =-$E$24*BV32*BV35/100 -> 0 | BW44: =-$E$24*BW32*BW35/100 -> 0 | BX44: =-$E$24*BX32*BX35/100 -> 0 | BY44: =-$E$24*BY32*BY35/100 -> 0 | BZ44: =-$E$24*BZ32*BZ35/100 -> 0 | CA44: =-$E$24*CA32*CA35/100 -> 0 | ... CN44: =-$E$24*CN32*CN35/100 -> 0 | CO44: =SUM(BT44:CN44) -> 0
C45: Depreciation - | E45: =$E$26*E32*E35/100 -> 0 | F45: =$E$26*F32*F35/100 -> 0 | G45: =$E$26*G32*G35/100 -> 0 | H45: =$E$26*H32*H35/100 -> 0 | I45: =$E$26*I32*I35/100 -> 0 | J45: =$E$26*J32*J35/100 -> 0 | K45: =$E$26*K32*K35/100 -> 0 | L45: =$E$26*L32*L35/100 -> 0 | ... Y45: =$E$26*Y32*Y35/100 -> 0 | Z45: =SUM(E45:Y45) -> 0 | AJ45: Depreciation - | AL45: =$E$26*AL32*AL35/100 -> 0 | AM45: =$E$26*AM32*AM35/100 -> 0 | AN45: =$E$26*AN32*AN35/100 -> 0 | AO45: =$E$26*AO32*AO35/100 -> 0 | AP45: =$E$26*AP32*AP35/100 -> 0 | AQ45: =$E$26*AQ32*AQ35/100 -> 0 | AR45: =$E$26*AR32*AR35/100 -> 0 | AS45: =$E$26*AS32*AS35/100 -> 0 | ... BF45: =$E$26*BF32*BF35/100 -> 0 | BG45: =SUM(AL45:BF45) -> 0 | BR45: Depreciation - | BT45: =$E$26*BT32*BT35/100 -> 0 | BU45: =$E$26*BU32*BU35/100 -> 0 | BV45: =$E$26*BV32*BV35/100 -> 0 | BW45: =$E$26*BW32*BW35/100 -> 0 | BX45: =$E$26*BX32*BX35/100 -> 0 | BY45: =$E$26*BY32*BY35/100 -> 0 | BZ45: =$E$26*BZ32*BZ35/100 -> 0 | CA45: =$E$26*CA32*CA35/100 -> 0 | ... CN45: =$E$26*CN32*CN35/100 -> 0 | CO45: =SUM(BT45:CN45) -> 0
AB47: StartTime=-12.5
...

Sheet ProjectCashflows - Depreciate
C1: CASE VARIABLES | D1: source capacity
C2: SweepValue1 | D2: 1
C3: SweepValue2 | D3: 2
C5: END TIME | D5: 2
C6: NUM STEPS | D6: 21
C7: PROJECT TIME | D7: 20
C8: DISCOUNT RATE | D8: 0.08
C9: Inflation | D9: 0
C10: Tax | D10: 0.25
C12: Source MACRS | D12: 7
C13: Source Lifetime | D13: 20
C15: PROJECT YEARS | E15: 0 | F15: 1 | G15: 2 | H15: 3 | I15: 4 | J15: 5 | K15: 6 | L15: 7 | M15: 8 | N15: 9 | O15: 10 | P15: 11 | Q15: 12 | R15: 13 | S15: 14 | T15: 15 | U15: 16 | V15: 17 | W15: 18 | X15: 19 | Y15: 20 | Z15: SUM | BR15: PROJECT YEARS | BT15: 0 | BU15: 1 | BV15: 2 | BW15: 3 | BX15: 4 | BY15: 5 | BZ15: 6 | CA15: 7 | CB15: 8 | CC15: 9 | CD15: 10 | CE15: 11 | CF15: 12 | CG15: 13 | CH15: 14 | CI15: 15 | CJ15: 16 | CK15: 17 | CL15: 18 | CM15: 19 | CN15: 20
C16: Tax Fraction | E16: =1-$D$10 -> 0.75 | F16: =1-$D$10 -> 0.75 | G16: =1-$D$10 -> 0.75 | H16: =1-$D$10 -> 0.75 | I16: =1-$D$10 -> 0.75 | J16: =1-$D$10 -> 0.75 | K16: =1-$D$10 -> 0.75 | L16: =1-$D$10 -> 0.75 | ... Y16: =1-$D$10 -> 0.75 | BR16: Tax Fraction | BT16: =1-$D$10 -> 0.75 | BU16: =1-$D$10 -> 0.75 | BV16: =1-$D$10 -> 0.75 | BW16: =1-$D$10 -> 0.75 | BX16: =1-$D$10 -> 0.75 | BY16: =1-$D$10 -> 0.75 | BZ16: =1-$D$10 -> 0.75 | CA16: =1-$D$10 -> 0.75 | ... CN16: =1-$D$10 -> 0.75
C17: Discount Rate | E17: =1/(1+$D$8)^E15 -> 1 | F17: =1/(1+$D$8)^F15 -> 0.92592593 | G17: =1/(1+$D$8)^G15 -> 0.85733882 | H17: =1/(1+$D$8)^H15 -> 0.79383224 | I17: =1/(1+$D$8)^I15 -> 0.73502985 | J17: =1/(1+$D$8)^J15 -> 0.6805832 | K17: =1/(1+$D$8)^K15 -> 0.63016963 | L17: =1/(1+$D$8)^L15 -> 0.5834904 | ... Y17: =1/(1+$D$8)^Y15 -> 0.21454821 | BR17: Discount Rate | BT17: =1/(1+$D$8)^BT15 -> 1 | BU17: =1/(1+$D$8)^BU15 -> 0.92592593 | BV17: =1/(1+$D$8)^BV15 -> 0.85733882 | BW17: =1/(1+$D$8)^BW15 -> 0.79383224 | BX17: =1/(1+$D$8)^BX15 -> 0.73502985 | BY17: =1/(1+$D$8)^BY15 -> 0.6805832 | BZ17: =1/(1+$D$8)^BZ15 -> 0.63016963 | CA17: =1/(1+$D$8)^CA15 -> 0.5834904 | ... CN17: =1/(1+$D$8)^CN15 -> 0.21454821
C18: MACRS Ammortization 7-Yr % | E18: 0 | F18: 14.29 | G18: 24.49 | H18: 17.49 | I18: 12.49 | J18: 8.93 | K18: 8.92 | L18: 8.93 | M18: 4.46 | N18: 0 | O18: 0 | P18: 0 | Q18: 0 | R18: 0 | S18: 0 | T18: 0 | U18: 0 | V18: 0 | W18: 0 | X18: 0 | Y18: 0 | BQ18: 7 | BR18: MACRS Ammortization 7-Yr % | BT18: 0 | BU18: 14.29 | BV18: 24.49 | BW18: 17.49 | BX18: 12.49 | BY18: 8.93 | BZ18: 8.92 | CA18: 8.93 | CB18: 4.46 | CC18: 0 | CD18: 0 | CE18: 0 | CF18: 0 | CG18: 0 | CH18: 0 | CI18: 0 | CJ18: 0 | CK18: 0 | CL18: 0 | CM18: 0 | CN18: 0
C19: MACRS Coefficient | E19: =E18/100 -> 0 | F19: =F18/100 -> 0.1429 | G19: =G18/100 -> 0.2449 | H19: =H18/100 -> 0.1749 | I19: =I18/100 -> 0.1249 | J19: =J18/100 -> 0.0893 | K19: =K18/100 -> 0.0892 | L19: =L18/100 -> 0.0893 | ... Y19: =Y18/100 -> 0 | AB19: StartTime=0 | BR19: MACRS Coefficient (7yr) | BT19: =BT18/100 -> 0 | BU19: =BU18/100 -> 0.1429 | BV19: =BV18/100 -> 0.2449 | BW19: =BW18/100 -> 0.1749 | BX19: =BX18/100 -> 0.1249 | BY19: =BY18/100 -> 0.0893 | BZ19: =BZ18/100 -> 0.0892 | CA19: =CA18/100 -> 0.0893 | ... CN19: =CN18/100 -> 0
B20: SweepValue1 | C20: CAPEX | E20: =$D$109*($D$2/$D$110)^$D$111 -> -1002.3052 | F20: 0 | G20: 0 | H20: 0 | I20: 0 | J20: 0 | K20: 0 | L20: 0 | M20: 0 | N20: 0 | O20: 0 | P20: 0 | Q20: 0 | R20: 0 | S20: 0 | T20: 0 | U20: 0 | V20: 0 | W20: 0 | X20: 0 | Y20: 0 | AB20: CORRECT | BQ20: 15 | BR20: MACRS Ammortization 15-Yr % | BT20: 0 | BU20: 5 | BV20: 9.5 | BW20: 8.55 | BX20: 7.7 | BY20: 6.93 | BZ20: 6.23 | CA20: 5.9 | CB20: 5.9 | CC20: 5.91 | CD20: 5.9 | CE20: 5.91 | CF20: 5.9 | CG20: 5.91 | CH20: 5.9 | CI20: 5.91 | CJ20: 2.95 | CK20: 0 | CL20: 0 | CM20: 0 | CN20: 0
C21: Summed Hourly Cashflow (already taxed) | E21: 0 | F21: =SweepValue1!$X$29*F17 -> 586.69162 | G21: =SweepValue1!$X$29*G17 -> 543.23298 | H21: =SweepValue1!$X$29*H17 -> 502.9935 | I21: =SweepValue1!$X$29*I17 -> 465.73472 | J21: =SweepValue1!$X$29*J17 -> 431.23585 | K21: =SweepValue1!$X$29*K17 -> 399.29246 | L21: =SweepValue1!$X$29*L17 -> 369.71524 | M21: =SweepValue1!$X$29*M17 -> 342.32892 | ... Y21: =SweepValue1!$X$29*Y17 -> 135.94353 | Z21: =SUM(E21:Y21) -> 6221.0428 | AA21: =SUM(Z21:Z24) -> 5661.2835 | BR21: MACRS Coefficient (15yr) | BT21: =BT20/100 -> 0 | BU21: =BU20/100 -> 0.05 | BV21: =BV20/100 -> 0.095 | BW21: =BW20/100 -> 0.0855 | BX21: =BX20/100 -> 0.077 | BY21: =BY20/100 -> 0.0693 | BZ21: =BZ20/100 -> 0.0623 | CA21: =CA20/100 -> 0.059 | ... CN21: =CN20/100 -> 0
C22: CAPEX Cashflow | E22: =E20*E16 -> -751.72893 | F22: =F20*F16 -> 0 | G22: =G20*G16 -> 0 | H22: =H20*H16 -> 0 | I22: =I20*I16 -> 0 | J22: =J20*J16 -> 0 | K22: =K20*K16 -> 0 | L22: =L20*L16 -> 0 | ... Y22: =Y20*Y16 -> 0 | Z22: =SUM(E22:Y22) -> -751.72893
C23: Depreciation + | E23: =-$E$20*E17/100*E18 -> 0 | F23: =-$E$20*F17*F19 -> 132.61983 | G23: =-$E$20*G17*G19 -> 210.44629 | H23: =-$E$20*H17*H19 -> 139.16132 | I23: =-$E$20*I17*I19 -> 92.016862 | J23: =-$E$20*J17*J19 -> 60.916183 | K23: =-$E$20*K17*K19 -> 56.340711 | L23: =-$E$20*L17*L19 -> 52.225808 | M23: =-$E$20*M17*M19 -> 24.151539 | ... X23: =-$E$20*X17*X19 -> 0 | Y23: =-$E$20*Y17/100*Y18 -> 0 | Z23: =SUM(E23:Y23) -> 767.87855
C24: Depreciation - | E24: =E18*E17/100*$E$22 -> 0 | F24: =-F23*F16 -> -99.464874 | G24: =-G23*G16 -> -157.83472 | H24: =-H23*H16 -> -104.37099 | I24: =-I23*I16 -> -69.012646 | J24: =-J23*J16 -> -45.687137 | K24: =-K23*K16 -> -42.255533 | L24: =-L23*L16 -> -39.169356 | M24: =-M23*M16 -> -18.113654 | ... X24: =-X23*X16 -> 0 | Y24: =Y18*Y17*$E$22 -> 0 | Z24: =SUM(E24:Y24) -> -575.90891
B25: SweepValue2 | C25: CAPEX | E25: =$D$109*($D$3/$D$110)^$D$111 -> -2003.2215 | F25: 0 | G25: 0 | H25: 0 | I25: 0 | J25: 0 | K25: 0 | L25: 0 | M25: 0 | N25: 0 | O25: 0 | P25: 0 | Q25: 0 | R25: 0 | S25: 0 | T25: 0 | U25: 0 | V25: 0 | W25: 0 | X25: 0 | Y25: 0
C26: Summed Hourly Cashflow (already taxed) | E26: 0 | F26: =SweepValue2!$X$29*F17 -> 1173.3961 | G26: =SweepValue2!$X$29*G17 -> 1086.4779 | H26: =SweepValue2!$X$29*H17 -> 1005.998 | I26: =SweepValue2!$X$29*I17 -> 931.47965 | J26: =SweepValue2!$X$29*J17 -> 862.48116 | K26: =SweepValue2!$X$29*K17 -> 798.59367 | L26: =SweepValue2!$X$29*L17 -> 739.43858 | M26: =SweepValue2!$X$29*M17 -> 684.66535 | ... Y26: =SweepValue2!$X$29*Y17 -> 271.89003 | Z26: =SUM(E26:Y26) -> 12442.222 | AA26: =SUM(Z26:Z29) -> 11323.479
C27: CAPEX Cashflow | E27: =E25*E16 -> -1502.4161 | F27: 0 | G27: 0 | H27: 0 | I27: 0 | J27: 0 | K27: 0 | L27: 0 | M27: 0 | N27: 0 | O27: 0 | P27: 0 | Q27: 0 | R27: 0 | S27: 0 | T27: 0 | U27: 0 | V27: 0 | W27: 0 | X27: 0 | Y27: 0 | Z27: =SUM(E27:Y27) -> -1502.4161
C28: Depreciation + | E28: =-$E$25*E17*E18/100 -> 0 | F28: =-$E$25*F17*F19 -> 265.05588 | G28: =-$E$25*G17*G19 -> 420.60094 | H28: =-$E$25*H17*H19 -> 278.12979 | I28: =-$E$25*I17*I19 -> 183.9062 | J28: =-$E$25*J17*J19 -> 121.74795 | K28: =-$E$25*K17*K19 -> 112.60334 | L28: =-$E$25*L17*L19 -> 104.37924 | M28: =-$E$25*M17*M19 -> 48.269609 | ... X28: =-$E$25*X17*X19 -> 0 | Y28: =-$E$25*Y17*Y18/100 -> 0 | Z28: =SUM(E28:Y28) -> 1534.693
C29: Depreciation - | E29: =$E$27*E17*E18/100 -> 0 | F29: =-F28*F16 -> -198.79191 | G29: =-G28*G16 -> -315.45071 | H29: =-H28*H16 -> -208.59734 | I29: =-I28*I16 -> -137.92965 | J29: =-J28*J16 -> -91.31096 | K29: =-K28*K16 -> -84.452508 | L29: =-L28*L16 -> -78.284431 | M29: =-M28*M16 -> -36.202207 | ... X29: =-X28*X16 -> 0 | Y29: =$E$27*Y17*Y18/100 -> 0 | Z29: =SUM(E29:Y29) -> -1151.0197
C33: Lifetime <= ProjectTime (Lifetime = 20) | AJ33: StartTime + Lifetime < ProjectTime Lifetime > ProjectTime (Lifetime = 25) | BR33: StartTime + Lifetime > ProjectTime |MACRS|+1 < |StartTime| (Lifetime = 40)
C36: PROJECT YEARS | E36: 0 | F36: 1 | G36: 2 | H36: 3 | I36: 4 | J36: 5 | K36: 6 | L36: 7 | M36: 8 | N36: 9 | O36: 10 | P36: 11 | Q36: 12 | R36: 13 | S36: 14 | T36: 15 | U36: 16 | V36: 17 | W36: 18 | X36: 19 | Y36: 20 | AJ36: PROJECT YEARS | AL36: 0 | AM36: 1 | AN36: 2 | AO36: 3 | AP36: 4 | AQ36: 5 | AR36: 6 | AS36: 7 | AT36: 8 | AU36: 9 | AV36: 10 | AW36: 11 | AX36: 12 | AY36: 13 | AZ36: 14 | BA36: 15 | BB36: 16 | BC36: 17 | BD36: 18 | BE36: 19 | BF36: 20 | BR36: PROJECT YEARS | BT36: 0 | BU36: 1 | BV36: 2 | BW36: 3 | BX36: 4 | BY36: 5 | BZ36: 6 | CA36: 7 | CB36: 8 | CC36: 9 | CD36: 10 | CE36: 11 | CF36: 12 | CG36: 13 | CH36: 14 | CI36: 15 | CJ36: 16 | CK36: 17 | CL36: 18 | CM36: 19 | CN36: 20
C37: COMPONENT YEARS | D37: Operations | E37: 5 | F37: 6 | G37: 7 | H37: 8 | I37: 9 | J37: 10 | K37: 11 | L37: 12 | M37: 13 | N37: 14 | O37: 15 | P37: 16 | Q37: 17 | R37: 18 | S37: 19 | T37: 20 | U37: 21 | V37: 22 | W37: 23 | X37: 24 | Y37: 25 | AJ37: COMPONENT YEARS | AK37: Operations | AL37: 10 | AM37: 11 | AN37: 12 | AO37: 13 | AP37: 14 | AQ37: 15 | AR37: 16 | AS37: 17 | AT37: 18 | AU37: 19 | AV37: 20 | AW37: 21 | AX37: 22 | AY37: 23 | AZ37: 24 | BA37: 25 | BB37: 26 | BC37: 27 | BD37: 28 | BE37: 29 | BF37: 30 | BR37: COMPONENT YEARS | BS37: Operations | BT37: 10 | BU37: 11 | BV37: 12 | BW37: 13 | BX37: 14 | BY37: 15 | BZ37: 16 | CA37: 17 | CB37: 18 | CC37: 19 | CD37: 20 | CE37: 21 | CF37: 22 | CG37: 23 | CH37: 24 | CI37: 25 | CJ37: 26 | CK37: 27 | CL37: 28 | CM37: 29 | CN37: 30
C38: COMPONENT YEARS | D38: Build | T38: SECOND | AJ38: COMPONENT YEARS | AK38: Build | BA38: SECOND | BR38: COMPONENT YEARS | BS38: Build
C39: MACRS YEARS | E39: 5 | F39: 6 | G39: 7 | H39: 8 | I39: 0 | J39: 0 | K39: 0 | L39: 0 | M39: 0 | N39: 0 | O39: 0 | P39: 0 | Q39: 0 | R39: 0 | S39: 0 | T39: 0 | U39: 1 | V39: 2 | W39: 3 | X39: 4 | Y39: 5 | AJ39: MACRS YEARS | AL39: 0 | AM39: 0 | AN39: 0 | AO39: 0 | AP39: 0 | AQ39: 0 | AR39: 0 | AS39: 0 | AT39: 0 | AU39: 0 | AV39: 0 | AW39: 0 | AX39: 0 | AY39: 0 | AZ39: 0 | BA39: 0 | BB39: 1 | BC39: 2 | BD39: 3 | BE39: 4 | BF39: 5 | BR39: MACRS YEARS | BT39: 0 | BU39: 0 | BV39: 0 | BW39: 0 | BX39: 0 | BY39: 0 | BZ39: 0 | CA39: 0 | CB39: 0 | CC39: 0 | CD39: 0 | CE39: 0 | CF39: 0 | CG39: 0 | CH39: 0 | CI39: 0 | CJ39: 0 | CK39: 0 | CL39: 0 | CM39: 0 | CN39: 0
C40: PROJECT YEARS | E40: -1 | F40: -2 | G40: -3 | H40: -4 | I40: -5 | AJ40: PROJECT YEARS | AL40: -1 | AM40: -2 | AN40: -3 | AO40: -4 | AP40: -5 | AQ40: -6 | AR40: -7 | AS40: -8 | AT40: -9 | AU40: -10 | BR40: PROJECT YEARS | BT40: -1 | BU40: -2 | BV40: -3 | BW40: -4 | BX40: -5 | BY40: -6 | BZ40: -7 | CA40: -8 | CB40: -9 | CC40: -10
C41: COMPONENT YEARS | D41: Operations | E41: 4 | F41: 3 | G41: 2 | H41: 1 | I41: - | AJ41: COMPONENT YEARS | AK41: Operations | AL41: 9 | AM41: 8 | AN41: 7 | AO41: 6 | AP41: 5 | AQ41: 4 | AR41: 3 | AS41: 2 | AT41: 1 | AU41: - | BR41: COMPONENT YEARS | BS41: Operations | BT41: 9 | BU41: 8 | BV41: 7 | BW41: 6 | BX41: 5 | BY41: 4 | BZ41: 3 | CA41: 2 | CB41: 1 | CC41: -
C42: COMPONENT YEARS | D42: Build | I42: FIRST | AJ42: COMPONENT YEARS | AK42: Build | AU42: FIRST | BR42: COMPONENT YEARS | BS42: Build | CC42: FIRST
C43: MACRS YEARS | E43: 4 | F43: 3 | G43: 2 | H43: 1 | I43: 0 | AJ43: MACRS YEARS | AL43: 0 | AM43: 8 | AN43: 7 | AO43: 6 | AP43: 5 | AQ43: 4 | AR43: 3 | AS43: 2 | AT43: 1 | AU43: 0 | BR43: MACRS YEARS | BT43: 0 | BU43: 8 | BV43: 7 | BW43: 6 | BX43: 5 | BY43: 4 | BZ43: 3 | CA43: 2 | CB43: 1 | CC43: 0
C45: PROJECT YEARS | E45: 0 | F45: 1 | G45: 2 | H45: 3 | I45: 4 | J45: 5 | K45: 6 | L45: 7 | M45: 8 | N45: 9 | O45: 10 | P45: 11 | Q45: 12 | R45: 13 | S45: 14 | T45: 15 | U45: 16 | V45: 17 | W45: 18 | X45: 19 | Y45: 20 | AJ45: PROJECT YEARS | AL45: 0 | AM45: 1 | AN45: 2 | AO45: 3 | AP45: 4 | AQ45: 5 | AR45: 6 | AS45: 7 | AT45: 8 | AU45: 9 | AV45: 10 | AW45: 11 | AX45: 12 | AY45: 13 | AZ45: 14 | BA45: 15 | BB45: 16 | BC45: 17 | BD45: 18 | BE45: 19 | BF45: 20 | BR45: PROJECT YEARS | BT45: 0 | BU45: 1 | BV45: 2 | BW45: 3 | BX45: 4 | BY45: 5 | BZ45: 6 | CA45: 7 | CB45: 8 | CC45: 9 | CD45: 10 | CE45: 11 | CF45: 12 | CG45: 13 | CH45: 14 | CI45: 15 | CJ45: 16 | CK45: 17 | CL45: 18 | CM45: 19 | CN45: 20
C46: MACRS YEARS | E46: 5 | F46: 6 | G46: 7 | H46: 8 | I46: 0 | J46: 0 | K46: 0 | L46: 0 | M46: 0 | N46: 0 | O46: 0 | P46: 0 | Q46: 0 | R46: 0 | S46: 0 | T46: 0 | U46: 1 | V46: 2 | W46: 3 | X46: 4 | Y46: 5 | AJ46: MACRS YEARS | AL46: 0 | AM46: 0 | AN46: 0 | AO46: 0 | AP46: 0 | AQ46: 0 | AR46: 0 | AS46: 0 | AT46: 0 | AU46: 0 | AV46: 0 | AW46: 0 | AX46: 0 | AY46: 0 | AZ46: 0 | BA46: 0 | BB46: 1 | BC46: 2 | BD46: 3 | BE46: 4 | BF46: 5 | BR46: MACRS YEARS | BT46: 0 | BU46: 0 | BV46: 0 | BW46: 0 | BX46: 0 | BY46: 0 | BZ46: 0 | CA46: 0 | CB46: 0 | CC46: 0 | CD46: 0 | CE46: 0 | CF46: 0 | CG46: 0 | CH46: 0 | CI46: 0 | CJ46: 0 | CK46: 0 | CL46: 0 | CM46: 0 | CN46: 0 | CQ46: MACRS 7yr
C47: MACRS Coefficient | E47: =J18/100 -> 0.0893 | F47: =K18/100 -> 0.0892 | G47: =L18/100 -> 0.0893 | H47: =M18/100 -> 0.0446 | I47: 0 | J47: 0 | K47: 0 | L47: 0 | M47: 0 | N47: 0 | O47: 0 | P47: 0 | Q47: 0 | R47: 0 | S47: 0 | T47: 0 | U47: =F18/100 -> 0.1429 | V47: =G18/100 -> 0.2449 | W47: =H18/100 -> 0.1749 | X47: =I18/100 -> 0.1249 | Y47: =J18/100 -> 0.0893 | AB47: StartTime=-5 | AJ47: MACRS Coefficient | AL47: 0 | AM47: 0 | AN47: 0 | AO47: 0 | AP47: 0 | AQ47: 0 | AR47: 0 | AS47: 0 | AT47: 0 | AU47: 0 | AV47: 0 | AW47: 0 | AX47: 0 | AY47: 0 | AZ47: 0 | BA47: 0 | BB47: =AM18/100 -> 0 | BC47: =AN18/100 -> 0 | BD47: =AO18/100 -> 0 | BE47: =AP18/100 -> 0 | BF47: =AQ18/100 -> 0 | BI47: StartTime=-10 | BR47: MACRS Coefficient | BT47: 0 | BU47: 0 | BV47: 0 | BW47: 0 | BX47: 0 | BY47: 0 | BZ47: 0 | CA47: 0 | CB47: 0 | CC47: 0 | CD47: 0 | CE47: 0 | CF47: 0 | CG47: 0 | CH47: 0 | CI47: 0 | CJ47: 0 | CK47: 0 | CL47: 0 | CM47: 0 | CN47: 0 | CQ47: StartTime=-10
B48: SweepValue1 | C48: CAPEX | E48: =E20 -> -1002.3052 | AB48: CORRECT | AI48: SweepValue1 | AJ48: CAPEX | AL48: =E48 -> -1002.3052 | BI48: CORRECT | BQ48: SweepValue1 | BR48: CAPEX | BT48: =AM48 -> 0 | CQ48: ERROR
C49: Summed Hourly Cashflow (already taxed) | E49: 0 | F49: =F21 -> 586.69162 | G49: =G21 -> 543.23298 | H49: =H21 -> 502.9935 | I49: =I21 -> 465.73472 | J49: =J21 -> 431.23585 | K49: =K21 -> 399.29246 | L49: =L21 -> 369.71524 | M49: =M21 -> 342.32892 | ... Y49: =Y21 -> 135.94353 | Z49: =SUM(E49:Y49) -> 6221.0428 | AA49: =SUM(Z49:Z52) -> 6105.2518 | AJ49: Summed Hourly Cashflow (already taxed) | AL49: 0 | AM49: =F49 -> 586.69162 | AN49: =G49 -> 543.23298 | AO49: =H49 -> 502.9935 | AP49: =I49 -> 465.73472 | AQ49: =J49 -> 431.23585 | AR49: =K49 -> 399.29246 | AS49: =L49 -> 369.71524 | AT49: =M49 -> 342.32892 | ... BF49: =Y49 -> 135.94353 | BG49: =SUM(AL49:BF49) -> 6221.0428 | BH49: =SUM(BG49:BG52) -> 6034.1237 | BR49: Summed Hourly Cashflow (already taxed) | BT49: 0 | BU49: =AN49 -> 543.23298 | BV49: =AO49 -> 502.9935 | BW49: =AP49 -> 465.73472 | BX49: =AQ49 -> 431.23585 | BY49: =AR49 -> 399.29246 | BZ49: =AS49 -> 369.71524 | CA49: =AT49 -> 342.32892 | CB49: =AU49 -> 316.97123 | ... CN49: =BG49 -> 6221.0428 | CO49: =SUM(BT49:CN49) -> 11855.394 | CP49: =SUM(CO49:CO52) -> 11855.394
...
